<?xml version="1.0" encoding="utf-8"?>
<!-- =================================================================================== -->
<!-- |    This document was autogenerated by xacro from model.xacro                    | -->
<!-- |    EDITING THIS FILE BY HAND IS NOT RECOMMENDED                                 | -->
<!-- =================================================================================== -->
<robot name="OPTIMUS_robot_001" xmlns:xacro="http://www.ros.org/wiki/xacro">
  <!-- Base Link -->
  <link name="base_link">
    <collision>
      <origin rpy="0 0 0" xyz="0 0 0"/>
      <geometry>
        <mesh filename="package://infi_sim_v1/models/OPTIMUS_robot_001/meshes/base_link_collision.stl" scale="1 1 1"/>
      </geometry>
    </collision>
    <!--<contact_coefficients> </contact_coefficients>-->
    <visual>
      <origin rpy="0 0 0" xyz="0 0 0"/>
      <geometry>
        <mesh filename="package://infi_sim_v1/models/OPTIMUS_robot_001/meshes/base_link.STL" scale="1 1 1"/>
      </geometry>
      <material name="orange"/>
    </visual>
    <inertial>
      <origin rpy="0 0 0" xyz="0.3 0 0.2"/>
      <mass value="50"/>
      <inertia ixx="5.0" ixy="0.0" ixz="0.0" iyy="5.0" iyz="0.0" izz="5.0"/>
    </inertial>
  </link>
  <gazebo reference="base_link">
    <mu1>0.1</mu1>
    <mu2>0.1</mu2>
    <kp>500000.0</kp>
    <kd>10.0</kd>
    <minDepth>0.001</minDepth>
    <maxVel>0.1</maxVel>
    <fdir1>1 0 0</fdir1>
    <material>Gazebo/FlatBlack</material>
  </gazebo>
  <joint name="j_whFL" type="continuous">
    <parent link="base_link"/>
    <child link="whFL"/>
    <origin rpy="0 0 0" xyz="0.4315 -0.185 0.0533"/>
    <axis xyz="0 1 0"/>
  </joint>
  <link name="whFL">
    <collision>
      <origin rpy="0 0 -1.5707963267948966" xyz="0 0 0"/>
      <geometry>
        <mesh filename="package://infi_sim_v1/models/OPTIMUS_robot_001/meshes/wheel_front_left.STL" scale="1 1 1"/>
      </geometry>
    </collision>
    <visual>
      <origin rpy="0 0 -1.5707963267948966" xyz="0 0 0"/>
      <geometry>
        <mesh filename="package://infi_sim_v1/models/OPTIMUS_robot_001/meshes/wheel_front_left.STL" scale="1 1 1"/>
      </geometry>
      <material name="orange"/>
    </visual>
    <inertial>
      <origin rpy="0 0 0" xyz="0 0 0"/>
      <mass value="1"/>
      <inertia ixx="0.2" ixy="0.0" ixz="0.0" iyy="0.2" iyz="0.0" izz="0.2"/>
    </inertial>
  </link>
  <joint name="j_whFR" type="continuous">
    <parent link="base_link"/>
    <child link="whFR"/>
    <origin rpy="0 0 0" xyz="0.4315 0.185 0.0533"/>
    <axis xyz="0 1 0"/>
  </joint>
  <link name="whFR">
    <collision>
      <origin rpy="0 0 1.5707963267948966" xyz="0 0 0"/>
      <geometry>
        <mesh filename="package://infi_sim_v1/models/OPTIMUS_robot_001/meshes/wheel_front_left.STL" scale="1 1 1"/>
      </geometry>
    </collision>
    <visual>
      <origin rpy="0 0 1.5707963267948966" xyz="0 0 0"/>
      <geometry>
        <mesh filename="package://infi_sim_v1/models/OPTIMUS_robot_001/meshes/wheel_front_left.STL" scale="1 1 1"/>
      </geometry>
      <material name="orange"/>
    </visual>
    <inertial>
      <origin rpy="0 0 0" xyz="0 0 0"/>
      <mass value="1"/>
      <inertia ixx="0.2" ixy="0.0" ixz="0.0" iyy="0.2" iyz="0.0" izz="0.2"/>
    </inertial>
  </link>
  <joint name="j_whRL" type="continuous">
    <parent link="base_link"/>
    <child link="whRL"/>
    <origin rpy="0 0 0" xyz="0.095 0.2075 -0.0173"/>
    <axis xyz="0 1 0"/>
  </joint>
  <link name="whRL">
    <collision>
      <origin rpy="1.5707963267948966 0 0" xyz="0 0 0"/>
      <!-- -1.5707963267948966  -->
      <geometry>
        <mesh filename="package://infi_sim_v1/models/OPTIMUS_robot_001/meshes/wheel_back_left.STL" scale="1 1 1"/>
      </geometry>
    </collision>
    <visual>
      <origin rpy="1.5707963267948966 0 0" xyz="0 0 0"/>
      <geometry>
        <mesh filename="package://infi_sim_v1/models/OPTIMUS_robot_001/meshes/wheel_back_left.STL" scale="1 1 1"/>
      </geometry>
      <material name="orange"/>
    </visual>
    <inertial>
      <origin rpy="0 0 0" xyz="0 0 0"/>
      <mass value="1"/>
      <inertia ixx="0.2" ixy="0.0" ixz="0.0" iyy="0.2" iyz="0.0" izz="0.2"/>
    </inertial>
  </link>
  <joint name="j_whRR" type="continuous">
    <parent link="base_link"/>
    <child link="whRR"/>
    <origin rpy="0 0 0" xyz="0.095 -0.2075 -0.0173"/>
    <axis xyz="0 1 0"/>
  </joint>
  <link name="whRR">
    <collision>
      <origin rpy="-1.5707963267948966 0 0" xyz="0 0 0"/>
      <!-- -1.5707963267948966  -->
      <geometry>
        <mesh filename="package://infi_sim_v1/models/OPTIMUS_robot_001/meshes/wheel_back_left.STL" scale="1 1 1"/>
      </geometry>
    </collision>
    <visual>
      <origin rpy="-1.5707963267948966 0 0" xyz="0 0 0"/>
      <geometry>
        <mesh filename="package://infi_sim_v1/models/OPTIMUS_robot_001/meshes/wheel_back_left.STL" scale="1 1 1"/>
      </geometry>
      <material name="orange"/>
    </visual>
    <inertial>
      <origin rpy="0 0 0" xyz="0 0 0"/>
      <mass value="1"/>
      <inertia ixx="0.2" ixy="0.0" ixz="0.0" iyy="0.2" iyz="0.0" izz="0.2"/>
    </inertial>
  </link>
  <joint name="j_elev" type="prismatic">
    <parent link="base_link"/>
    <child link="elevator"/>
    <origin rpy="0 0 0" xyz="0.4065 0 0.595"/>
    <axis xyz="0 0 1"/>
    <limit effort="30" lower="0" upper="0.7" velocity="1.0"/>
  </joint>
  <link name="elevator">
    <collision>
      <origin rpy="0 0 0" xyz="0 0 0"/>
      <!-- -1.5707963267948966  -->
      <geometry>
        <mesh filename="package://infi_sim_v1/models/OPTIMUS_robot_001/meshes/elevator_robotic_arm.STL" scale="1 1 1"/>
      </geometry>
    </collision>
    <visual>
      <origin rpy="0 0 0" xyz="0 0 0"/>
      <geometry>
        <mesh filename="package://infi_sim_v1/models/OPTIMUS_robot_001/meshes/elevator_robotic_arm.STL" scale="1 1 1"/>
      </geometry>
      <material name="orange"/>
    </visual>
    <inertial>
      <origin rpy="0 0 0" xyz="0 0 0"/>
      <mass value="1"/>
      <inertia ixx="0.2" ixy="0.0" ixz="0.0" iyy="0.2" iyz="0.0" izz="0.2"/>
    </inertial>
  </link>
  <gazebo reference="whRL">
    <mu1>0.0000001</mu1>
    <mu2>0.0000001</mu2>
    <kp>500000.0</kp>
    <kd>10.0</kd>
    <minDepth>0.001</minDepth>
    <maxVel>0.1</maxVel>
    <fdir1>1 0 0</fdir1>
    <material>Gazebo/Orange</material>
  </gazebo>
  <gazebo reference="whRR">
    <mu1>0.0000001</mu1>
    <mu2>0.0000001</mu2>
    <kp>500000.0</kp>
    <kd>10.0</kd>
    <minDepth>0.001</minDepth>
    <maxVel>0.1</maxVel>
    <fdir1>1 0 0</fdir1>
    <material>Gazebo/Orange</material>
  </gazebo>
</robot>

